Workbook

Sheet Tabelle1
A1: Projektübersicht Q4/2025
A2: Stand: aktuell
A4: ID | B4: Projektname | C4: Budget | D4: Status | E4: Verantwortlich
A5: PRJ-001 | B5: Website Relaunch | C5: 150000 | D5: aktiv | E5: Müller
A6: PRJ-02 | B6: ERP Migration | C6: 500000 | D6: aktiv | E6: Schmidt
A7: PRJ-003 | B7: Mobile App | C7: noch offen | D7: geplant | E7: Weber
A8: PRJ-004 | B8: Data Warehouse | C8: 300000 | D8: aktiv | E8: Fischer
A10: PRJ-006 | B10: CRM Update | C10: 80000 | D10: abgeschlossen | E10: Wagner
A11: PRJ-007 | B11: Security Audit | C11: 45000 | D11: aktiv | E11: Bauer
A12: PRJ-007 | B12: Security Audit v2 | C12: 48000 | D12: aktiv | E12: Bauer

Sheet Hilfstabelle
A1: MWSt-Satz | B1: 0.2
A2: Rabatt | B2: 0.15

Sheet Kopie von Tabelle1 (2)
A1: Alte Version - nicht verwenden

Sheet Berechnungen
A1: Heute | B1: =HEUTE()
A2: Berechnung | B2: =SUMME($C$5:$C$100)*1.2*0.85
A3: Verweis | B3: =SVERWEIS(A5,Tabelle1!A:E,3,FALSCH)
A5: =SVERWEIS(A5,Tabelle1!A:E,2,FALSCH) | B5: =WENN(A5>1000,A5*0.19,A5*0.07)
A6: =SVERWEIS(A6,Tabelle1!A:E,3,FALSCH) | B6: =WENN(A6>1000,A6*0.19,A6*0.07)
A7: =SVERWEIS(A7,Tabelle1!A:E,4,FALSCH) | B7: =WENN(A7>1000,A7*0.19,A7*0.07)
A8: =SVERWEIS(A8,Tabelle1!A:E,1,FALSCH) | B8: =WENN(A8>1000,A8*0.19,A8*0.07)
A9: =SVERWEIS(A9,Tabelle1!A:E,2,FALSCH) | B9: =WENN(A9>1000,A9*0.19,A9*0.07)
A10: =SVERWEIS(A10,Tabelle1!A:E,3,FALSCH) | B10: =WENN(A10>1000,A10*0.19,A10*0.07)
A11: =SVERWEIS(A11,Tabelle1!A:E,4,FALSCH) | B11: =WENN(A11>1000,A11*0.19,A11*0.07)
A12: =SVERWEIS(A12,Tabelle1!A:E,1,FALSCH) | B12: =WENN(A12>1000,A12*0.19,A12*0.07)
A13: =SVERWEIS(A13,Tabelle1!A:E,2,FALSCH) | B13: =WENN(A13>1000,A13*0.19,A13*0.07)
A14: =SVERWEIS(A14,Tabelle1!A:E,3,FALSCH) | B14: =WENN(A14>1000,A14*0.19,A14*0.07)
A15: =SVERWEIS(A15,Tabelle1!A:E,4,FALSCH) | B15: =WENN(A15>1000,A15*0.19,A15*0.07)
A16: =SVERWEIS(A16,Tabelle1!A:E,1,FALSCH) | B16: =WENN(A16>1000,A16*0.19,A16*0.07)
A17: =SVERWEIS(A17,Tabelle1!A:E,2,FALSCH) | B17: =WENN(A17>1000,A17*0.19,A17*0.07)
A18: =SVERWEIS(A18,Tabelle1!A:E,3,FALSCH) | B18: =WENN(A18>1000,A18*0.19,A18*0.07)
A19: =SVERWEIS(A19,Tabelle1!A:E,4,FALSCH) | B19: =WENN(A19>1000,A19*0.19,A19*0.07)
A20: =SVERWEIS(A20,Tabelle1!A:E,1,FALSCH) | B20: =WENN(A20>1000,A20*0.19,A20*0.07)
A21: =SVERWEIS(A21,Tabelle1!A:E,2,FALSCH) | B21: =WENN(A21>1000,A21*0.19,A21*0.07)
A22: =SVERWEIS(A22,Tabelle1!A:E,3,FALSCH) | B22: =WENN(A22>1000,A22*0.19,A22*0.07)
A23: =SVERWEIS(A23,Tabelle1!A:E,4,FALSCH) | B23: =WENN(A23>1000,A23*0.19,A23*0.07)
A24: =SVERWEIS(A24,Tabelle1!A:E,1,FALSCH) | B24: =WENN(A24>1000,A24*0.19,A24*0.07)
A25: =SVERWEIS(A25,Tabelle1!A:E,2,FALSCH) | B25: =WENN(A25>1000,A25*0.19,A25*0.07)
A26: =SVERWEIS(A26,Tabelle1!A:E,3,FALSCH) | B26: =WENN(A26>1000,A26*0.19,A26*0.07)
A27: =SVERWEIS(A27,Tabelle1!A:E,4,FALSCH) | B27: =WENN(A27>1000,A27*0.19,A27*0.07)
A28: =SVERWEIS(A28,Tabelle1!A:E,1,FALSCH) | B28: =WENN(A28>1000,A28*0.19,A28*0.07)
A29: =SVERWEIS(A29,Tabelle1!A:E,2,FALSCH) | B29: =WENN(A29>1000,A29*0.19,A29*0.07)
A30: =SVERWEIS(A30,Tabelle1!A:E,3,FALSCH) | B30: =WENN(A30>1000,A30*0.19,A30*0.07)
A31: =SVERWEIS(A31,Tabelle1!A:E,4,FALSCH) | B31: =WENN(A31>1000,A31*0.19,A31*0.07)
A32: =SVERWEIS(A32,Tabelle1!A:E,1,FALSCH) | B32: =WENN(A32>1000,A32*0.19,A32*0.07)
A33: =SVERWEIS(A33,Tabelle1!A:E,2,FALSCH) | B33: =WENN(A33>1000,A33*0.19,A33*0.07)
A34: =SVERWEIS(A34,Tabelle1!A:E,3,FALSCH) | B34: =WENN(A34>1000,A34*0.19,A34*0.07)
A35: =SVERWEIS(A35,Tabelle1!A:E,4,FALSCH) | B35: =WENN(A35>1000,A35*0.19,A35*0.07)
A36: =SVERWEIS(A36,Tabelle1!A:E,1,FALSCH) | B36: =WENN(A36>1000,A36*0.19,A36*0.07)
A37: =SVERWEIS(A37,Tabelle1!A:E,2,FALSCH) | B37: =WENN(A37>1000,A37*0.19,A37*0.07)
A38: =SVERWEIS(A38,Tabelle1!A:E,3,FALSCH) | B38: =WENN(A38>1000,A38*0.19,A38*0.07)
A39: =SVERWEIS(A39,Tabelle1!A:E,4,FALSCH) | B39: =WENN(A39>1000,A39*0.19,A39*0.07)
A40: =SVERWEIS(A40,Tabelle1!A:E,1,FALSCH) | B40: =WENN(A40>1000,A40*0.19,A40*0.07)
A41: =SVERWEIS(A41,Tabelle1!A:E,2,FALSCH) | B41: =WENN(A41>1000,A41*0.19,A41*0.07)
...
